<?xml version="1.0" ?>
<sdf version="1.9">
  <world name="city_for_car">
    <!-- ŚWIATŁO / SŁOŃCE -->
    <!-- Trawa jako podłoże -->
    <model name="grass_ground">
      <pose>0 0 -0.1 0 0 0</pose>
      <static>true</static>
      <link name="link">
        <collision name="col">
          <geometry>
            <box><size>200 200 0.2</size></box>
          </geometry>
        </collision>
        <visual name="vis_grass">
          <geometry>
            <box><size>200 200 0.2</size></box>
          </geometry>
          <material>
            <ambient>0.2 0.6 0.2 1</ambient>
            <diffuse>0.2 0.8 0.2 1</diffuse>
          </material>
        </visual>
      </link>
    </model>
    <light name="city_sun" type="directional">
      <cast_shadows>true</cast_shadows>
      <pose>0 0 10 0.4 0.0 0</pose>
      <diffuse>1 1 1 1</diffuse>
      <specular>0.2 0.2 0.2 1</specular>
      <attenuation>
        <range>200</range>
        <constant>0.9</constant>
        <linear>0.01</linear>
        <quadratic>0.001</quadratic>
      </attenuation>
      <direction>-0.5 0.3 -1</direction>
    </light>

    <!-- PROSTA SCENA MIASTA -->
    <!-- Oś: X (wschód-zachód), Y (północ-południe) -->

    <include>
      <uri>model://road</uri>
      <name>veritcal_road_1</name>
      <pose>0 0 0 0 0 0</pose>
    </include>
    <include>
      <uri>model://road</uri>
      <name>vertical_road_2</name>
      <pose>0 40 0 0 0 0</pose>
    </include>
    <include>
      <uri>model://road</uri>
      <name>vertical_road_3</name>
      <pose>0 -40 0 0 0 0</pose>
    </include>

    <include>
      <uri>model://road</uri>
      <name>horizontal_road_1</name>
      <pose>0 0 0 0 0 1.57</pose>
    </include>
    <include>
      <uri>model://road</uri>
      <name>horizontal_road_2</name>
      <pose>40 0 0 0 0 1.57</pose>
    </include>
    <include>
      <uri>model://road</uri>
      <name>horizontal_road_3</name>
      <pose>-40 0 0 0 0 1.57</pose>
    </include>

    <include>
      <uri>model://road_curve</uri>
      <name>road_curve_1</name>
      <pose> 40 -30 0 0 0 0</pose>
    </include>



    <!-- PROSTE BUDYNKI (BOX) -->
    <!-- <model name="building_1">
      <pose>-15 12 5 0 0 0</pose>
      <static>true</static>
      <link name="link">
        <collision name="col"><geometry><box><size>10 10 10</size></box></geometry></collision>
        <visual name="vis"><geometry><box><size>10 10 10</size></box></geometry>
          <material><ambient>0.3 0.3 0.8 1</ambient><diffuse>0.3 0.3 0.8 1</diffuse></material>
        </visual>
      </link>
    </model> -->

    <include>
      <uri>model://simple_building</uri>
      <name>simple_building</name>
      <pose>-15 12 5 0 0 0</pose>
    </include>

    <include>
      <uri>model://simple_building</uri>
      <name>simple_building2</name>
      <pose>-10 12 5 0 0 0</pose>
    </include>

    <include>
      <uri>model://house_3</uri>
      <name>house_3</name>
      <pose>20 25 0 0 0 0</pose>
    </include>

    <include>
      <uri>model://house_1</uri>
      <name>house_1</name>
      <pose>-25 25 0 0 0 0</pose>
    </include>

        <include>
      <uri>model://house_2</uri>
      <name>house_2</name>
      <pose>-10 -55 0 0 0 0</pose>
    </include>


    <model name="building_2">
      <pose>18 10 7.5 0 0 0</pose>
      <static>true</static>
      <link name="link">
        <collision name="col"><geometry><box><size>8 8 15</size></box></geometry></collision>
        <visual name="vis"><geometry><box><size>8 8 15</size></box></geometry>
          <material><ambient>0.6 0.4 0.2 1</ambient><diffuse>0.6 0.4 0.2 1</diffuse></material>
        </visual>
      </link>
    </model>



    <model name="building_3">
      <pose>-20 -14 4 0 0 0</pose>
      <static>true</static>
      <link name="link">
        <collision name="col"><geometry><box><size>12 12 8</size></box></geometry></collision>
        <visual name="vis"><geometry><box><size>12 12 8</size></box></geometry>
          <material><ambient>0.25 0.5 0.25 1</ambient><diffuse>0.25 0.5 0.25 1</diffuse></material>
        </visual>
      </link>
    </model>
    <model name="building_4">
      <pose>22 -16 6 0 0 0</pose>
      <static>true</static>
      <link name="link">
        <collision name="col"><geometry><box><size>10 10 12</size></box></geometry></collision>
        <visual name="vis"><geometry><box><size>10 10 12</size></box></geometry>
          <material><ambient>0.5 0.2 0.5 1</ambient><diffuse>0.5 0.2 0.5 1</diffuse></material>
        </visual>
      </link>
    </model>

    <model name="building_5">
      <pose>30 -20 4 0 0 0</pose>
      <static>true</static>
      <link name="link">
        <collision name="col"><geometry><box><size>12 12 8</size></box></geometry></collision>
        <visual name="vis"><geometry><box><size>12 12 8</size></box></geometry>
          <material><ambient>0.25 0.5 0.25 1</ambient><diffuse>0.25 0.5 0.25 1</diffuse></material>
        </visual>
      </link>
    </model>

    <include>
      <uri>model://vehicle</uri>
      <name>vehicle_1</name>
      <pose>0 0 0.5 0 0 0</pose>
    </include>
        
  </world>
</sdf>



    <!-- INLINE VEHICLE MODEL (was include model://vehicle which failed to resolve)
    <model name='vehicle'>
      <!-- Dalsze obniżenie Z z 0.425 do 0.35 dla lepszego kontaktu kół z powierzchnią -->
  <pose>0 0 0.5 0 0 0</pose>
      <static>false</static>
      <link name='chassis'>
        <pose>-0.151427 0 0.175 0 0 0</pose>
        <inertial>
          <mass>1.14395</mass>
          <inertia>
            <ixx>0.126164</ixx><ixy>0</ixy><ixz>0</ixz>
            <iyy>0.416519</iyy><iyz>0</iyz>
            <izz>0.481014</izz>
          </inertia>
        </inertial>
        <visual name='visual_chassis'>
          <geometry>
            <box><size>2.01142 1 0.568726</size></box>
          </geometry>
          <material>
            <ambient>0.5 0.5 1.0 1</ambient>
            <diffuse>0.5 0.5 1.0 1</diffuse>
            <specular>0.0 0.0 1.0 1</specular>
          </material>
        </visual>
        <collision name='collision_chassis'>
          <geometry>
            <box><size>2.01142 1 0.568726</size></box>
          </geometry>
        </collision>
      </link>
      <link name='left_wheel'>
        <pose>0.554283 0.625029 -0.025 -1.5707 0 0</pose>
        <inertial>
          <mass>2</mass>
          <inertia>
            <ixx>0.145833</ixx><ixy>0</ixy><ixz>0</ixz>
            <iyy>0.145833</iyy><iyz>0</iyz>
            <izz>0.125</izz>
          </inertia>
        </inertial>
        <visual name='visual_left_wheel'>
          <geometry>
            <cylinder>
              <radius>0.3</radius>
              <length>0.1</length>
            </cylinder>
          </geometry>
          <material>
            <ambient>0.2 0.2 0.2 1</ambient>
            <diffuse>0.2 0.2 0.2 1</diffuse>
            <specular>0.2 0.2 0.2 1</specular>
          </material>
        </visual>
        <collision name='collision_left_wheel'>
          <geometry>
            <cylinder>
              <radius>0.3</radius>
              <length>0.1</length>
            </cylinder>
          </geometry>
          <surface>
            <friction>
              <ode>
                <mu>1.0</mu>
                <mu2>1.0</mu2>
              </ode>
            </friction>
          </surface>
        </collision>
      </link>
      <link name='right_wheel'>
        <pose>0.554282 -0.625029 -0.025 -1.5707 0 0</pose>
        <inertial>
          <mass>2</mass>
          <inertia>
            <ixx>0.145833</ixx><ixy>0</ixy><ixz>0</ixz>
            <iyy>0.145833</iyy><iyz>0</iyz>
            <izz>0.125</izz>
          </inertia>
        </inertial>
        <visual name='visual_right_wheel'>
          <geometry>
            <cylinder>
              <radius>0.3</radius>
              <length>0.1</length>
            </cylinder>
          </geometry>
          <material>
            <ambient>0.2 0.2 0.2 1</ambient>
            <diffuse>0.2 0.2 0.2 1</diffuse>
            <specular>0.2 0.2 0.2 1</specular>
          </material>
        </visual>
        <collision name='collision_right_wheel'>
          <geometry>
            <cylinder>
              <radius>0.3</radius>
              <length>0.1</length>
            </cylinder>
          </geometry>
          <surface>
            <friction>
              <ode>
                <mu>1.0</mu>
                <mu2>1.0</mu2>
              </ode>
            </friction>
          </surface>
        </collision>
      </link>
      <link name='caster'>
        <pose>-0.957138 0 -0.125 0 0 0</pose>
        <inertial>
          <mass>1</mass>
          <inertia>
            <ixx>0.1</ixx><ixy>0</ixy><ixz>0</ixz>
            <iyy>0.1</iyy><iyz>0</iyz>
            <izz>0.1</izz>
          </inertia>
        </inertial>
        <visual name='visual_caster'>
          <geometry><sphere><radius>0.2</radius></sphere></geometry>
          <material>
            <ambient>0.2 0.2 0.2 1</ambient>
            <diffuse>0.2 0.2 0.2 1</diffuse>
            <specular>0.2 0.2 0.2 1</specular>
          </material>
        </visual>
        <collision name='collision_caster'>
          <geometry><sphere><radius>0.2</radius></sphere></geometry>
        </collision>
      </link>
      <joint name='left_wheel_joint' type='revolute'>
        <parent>chassis</parent>
        <child>left_wheel</child>
        <axis>
          <!-- Oś zmieniona z (0 0 1) na (0 1 0) zgodnie z klasycznym układem diff-drive (obrót koła wokół osi Y) -->
          <xyz>0 1 0</xyz>
          <limit><lower>-1e16</lower><upper>1e16</upper></limit>
        </axis>
      </joint>
      <joint name='right_wheel_joint' type='revolute'>
        <parent>chassis</parent>
        <child>right_wheel</child>
        <axis>
          <!-- Oś zmieniona z (0 0 1) na (0 1 0) -->
          <xyz>0 1 0</xyz>
          <limit><lower>-1e16</lower><upper>1e16</upper></limit>
        </axis>
      </joint>
      <joint name='caster_wheel' type='ball'>
        <parent>chassis</parent>
        <child>caster</child>
      </joint>
      <plugin filename='gz-sim-diff-drive-system' name='gz::sim::systems::DiffDrive'>
        <left_joint>left_wheel_joint</left_joint>
        <right_joint>right_wheel_joint</right_joint>
        <wheel_separation>1.25</wheel_separation>
        <wheel_radius>0.3</wheel_radius>
        <odom_publish_frequency>10</odom_publish_frequency>
        <odom_frame>odom</odom_frame>
        <base_frame>base_link</base_frame>
        <max_linear_acceleration>1</max_linear_acceleration>
        <min_linear_acceleration>-1</min_linear_acceleration>
        <max_angular_acceleration>2</max_angular_acceleration>
        <min_angular_acceleration>-2</min_angular_acceleration>
        <max_linear_velocity>0.5</max_linear_velocity>
        <min_linear_velocity>-0.5</min_linear_velocity>
        <max_angular_velocity>1</max_angular_velocity>
        <min_angular_velocity>-1</min_angular_velocity>
        <topic>cmd_vel</topic>
        <odom_topic>odom</odom_topic>
      </plugin>
    </model> -->
